Workbook

Sheet สรุป
A1: นิติมิตร — รายการฟีเจอร์ MVP (เฟส P0 + P1)
A2: ที่มา: docs/02-srs.md (ฉบับ 1.8, 1 ต.ค. 2569) · สถานะตรวจเทียบโค้ดและหน้าจอจริง ณ 1 ต.ค. 2569 · ตัวเลขทุกช่องในหน้านี้คำนวณจากชีต “ฟีเจอร์ MVP” อัตโนมัติ
A4: รหัสโมดูล | B4: โมดูล | C4: กลุ่ม requirement | D4: จำนวนฟีเจอร์ | E4: Must | F4: Should | G4: Could | H4: P0 (วางฐาน) | I4: P1 (MVP) | J4: เสร็จแล้ว | K4: % เสร็จ | L4: กำลังทำ | M4: ยังไม่เริ่ม
A5: M1 | B5: บัญชีผู้ใช้และการเข้าถึง | C5: FR-AUTH | D5: =COUNTIFS('ฟีเจอร์ MVP'!$B:$B,$C5&"-*") -> 23 | E5: =COUNTIFS('ฟีเจอร์ MVP'!$B:$B,$C5&"-*",'ฟีเจอร์ MVP'!$H:$H,"Must*") -> 17 | F5: =COUNTIFS('ฟีเจอร์ MVP'!$B:$B,$C5&"-*",'ฟีเจอร์ MVP'!$H:$H,"Should*") -> 6 | G5: =COUNTIFS('ฟีเจอร์ MVP'!$B:$B,$C5&"-*",'ฟีเจอร์ MVP'!$H:$H,"Could*") -> 0 | H5: =COUNTIFS('ฟีเจอร์ MVP'!$B:$B,$C5&"-*",'ฟีเจอร์ MVP'!$I:$I,"P0") -> 6 | I5: =COUNTIFS('ฟีเจอร์ MVP'!$B:$B,$C5&"-*",'ฟีเจอร์ MVP'!$I:$I,"P1") -> 17 | J5: =COUNTIFS('ฟีเจอร์ MVP'!$B:$B,$C5&"-*",'ฟีเจอร์ MVP'!$L:$L,"เสร็จแล้ว") -> 13 | K5: =IFERROR(J5/D5,0) -> 0.56521739 | L5: =COUNTIFS('ฟีเจอร์ MVP'!$B:$B,$C5&"-*",'ฟีเจอร์ MVP'!$L:$L,"กำลังทำ") -> 10 | M5: =COUNTIFS('ฟีเจอร์ MVP'!$B:$B,$C5&"-*",'ฟีเจอร์ MVP'!$L:$L,"ยังไม่เริ่ม") -> 0
A6: M2 | B6: แชทถามกฎหมาย (หน้าจอและการใช้งาน) | C6: FR-CHAT | D6: =COUNTIFS('ฟีเจอร์ MVP'!$B:$B,$C6&"-*") -> 31 | E6: =COUNTIFS('ฟีเจอร์ MVP'!$B:$B,$C6&"-*",'ฟีเจอร์ MVP'!$H:$H,"Must*") -> 16 | F6: =COUNTIFS('ฟีเจอร์ MVP'!$B:$B,$C6&"-*",'ฟีเจอร์ MVP'!$H:$H,"Should*") -> 14 | G6: =COUNTIFS('ฟีเจอร์ MVP'!$B:$B,$C6&"-*",'ฟีเจอร์ MVP'!$H:$H,"Could*") -> 1 | H6: =COUNTIFS('ฟีเจอร์ MVP'!$B:$B,$C6&"-*",'ฟีเจอร์ MVP'!$I:$I,"P0") -> 0 | I6: =COUNTIFS('ฟีเจอร์ MVP'!$B:$B,$C6&"-*",'ฟีเจอร์ MVP'!$I:$I,"P1") -> 31 | J6: =COUNTIFS('ฟีเจอร์ MVP'!$B:$B,$C6&"-*",'ฟีเจอร์ MVP'!$L:$L,"เสร็จแล้ว") -> 23 | K6: =IFERROR(J6/D6,0) -> 0.74193548 | L6: =COUNTIFS('ฟีเจอร์ MVP'!$B:$B,$C6&"-*",'ฟีเจอร์ MVP'!$L:$L,"กำลังทำ") -> 8 | M6: =COUNTIFS('ฟีเจอร์ MVP'!$B:$B,$C6&"-*",'ฟีเจอร์ MVP'!$L:$L,"ยังไม่เริ่ม") -> 0
A7: M2 | B7: แชทถามกฎหมาย (เครื่องตอบ/ค้นหา/Guardrails) | C7: FR-AI | D7: =COUNTIFS('ฟีเจอร์ MVP'!$B:$B,$C7&"-*") -> 14 | E7: =COUNTIFS('ฟีเจอร์ MVP'!$B:$B,$C7&"-*",'ฟีเจอร์ MVP'!$H:$H,"Must*") -> 13 | F7: =COUNTIFS('ฟีเจอร์ MVP'!$B:$B,$C7&"-*",'ฟีเจอร์ MVP'!$H:$H,"Should*") -> 1 | G7: =COUNTIFS('ฟีเจอร์ MVP'!$B:$B,$C7&"-*",'ฟีเจอร์ MVP'!$H:$H,"Could*") -> 0 | H7: =COUNTIFS('ฟีเจอร์ MVP'!$B:$B,$C7&"-*",'ฟีเจอร์ MVP'!$I:$I,"P0") -> 0 | I7: =COUNTIFS('ฟีเจอร์ MVP'!$B:$B,$C7&"-*",'ฟีเจอร์ MVP'!$I:$I,"P1") -> 14 | J7: =COUNTIFS('ฟีเจอร์ MVP'!$B:$B,$C7&"-*",'ฟีเจอร์ MVP'!$L:$L,"เสร็จแล้ว") -> 6 | K7: =IFERROR(J7/D7,0) -> 0.42857143 | L7: =COUNTIFS('ฟีเจอร์ MVP'!$B:$B,$C7&"-*",'ฟีเจอร์ MVP'!$L:$L,"กำลังทำ") -> 8 | M7: =COUNTIFS('ฟีเจอร์ MVP'!$B:$B,$C7&"-*",'ฟีเจอร์ MVP'!$L:$L,"ยังไม่เริ่ม") -> 0
A8: M3 | B8: คลังความรู้ | C8: FR-KB | D8: =COUNTIFS('ฟีเจอร์ MVP'!$B:$B,$C8&"-*") -> 12 | E8: =COUNTIFS('ฟีเจอร์ MVP'!$B:$B,$C8&"-*",'ฟีเจอร์ MVP'!$H:$H,"Must*") -> 10 | F8: =COUNTIFS('ฟีเจอร์ MVP'!$B:$B,$C8&"-*",'ฟีเจอร์ MVP'!$H:$H,"Should*") -> 2 | G8: =COUNTIFS('ฟีเจอร์ MVP'!$B:$B,$C8&"-*",'ฟีเจอร์ MVP'!$H:$H,"Could*") -> 0 | H8: =COUNTIFS('ฟีเจอร์ MVP'!$B:$B,$C8&"-*",'ฟีเจอร์ MVP'!$I:$I,"P0") -> 0 | I8: =COUNTIFS('ฟีเจอร์ MVP'!$B:$B,$C8&"-*",'ฟีเจอร์ MVP'!$I:$I,"P1") -> 12 | J8: =COUNTIFS('ฟีเจอร์ MVP'!$B:$B,$C8&"-*",'ฟีเจอร์ MVP'!$L:$L,"เสร็จแล้ว") -> 5 | K8: =IFERROR(J8/D8,0) -> 0.41666667 | L8: =COUNTIFS('ฟีเจอร์ MVP'!$B:$B,$C8&"-*",'ฟีเจอร์ MVP'!$L:$L,"กำลังทำ") -> 7 | M8: =COUNTIFS('ฟีเจอร์ MVP'!$B:$B,$C8&"-*",'ฟีเจอร์ MVP'!$L:$L,"ยังไม่เริ่ม") -> 0
A9: M5 | B9: คู่มือขั้นตอน | C9: FR-GUIDE | D9: =COUNTIFS('ฟีเจอร์ MVP'!$B:$B,$C9&"-*") -> 7 | E9: =COUNTIFS('ฟีเจอร์ MVP'!$B:$B,$C9&"-*",'ฟีเจอร์ MVP'!$H:$H,"Must*") -> 3 | F9: =COUNTIFS('ฟีเจอร์ MVP'!$B:$B,$C9&"-*",'ฟีเจอร์ MVP'!$H:$H,"Should*") -> 4 | G9: =COUNTIFS('ฟีเจอร์ MVP'!$B:$B,$C9&"-*",'ฟีเจอร์ MVP'!$H:$H,"Could*") -> 0 | H9: =COUNTIFS('ฟีเจอร์ MVP'!$B:$B,$C9&"-*",'ฟีเจอร์ MVP'!$I:$I,"P0") -> 0 | I9: =COUNTIFS('ฟีเจอร์ MVP'!$B:$B,$C9&"-*",'ฟีเจอร์ MVP'!$I:$I,"P1") -> 7 | J9: =COUNTIFS('ฟีเจอร์ MVP'!$B:$B,$C9&"-*",'ฟีเจอร์ MVP'!$L:$L,"เสร็จแล้ว") -> 7 | K9: =IFERROR(J9/D9,0) -> 1 | L9: =COUNTIFS('ฟีเจอร์ MVP'!$B:$B,$C9&"-*",'ฟีเจอร์ MVP'!$L:$L,"กำลังทำ") -> 0 | M9: =COUNTIFS('ฟีเจอร์ MVP'!$B:$B,$C9&"-*",'ฟีเจอร์ MVP'!$L:$L,"ยังไม่เริ่ม") -> 0
A10: M6 | B10: แบบหนังสือ | C10: FR-TPL | D10: =COUNTIFS('ฟีเจอร์ MVP'!$B:$B,$C10&"-*") -> 9 | E10: =COUNTIFS('ฟีเจอร์ MVP'!$B:$B,$C10&"-*",'ฟีเจอร์ MVP'!$H:$H,"Must*") -> 8 | F10: =COUNTIFS('ฟีเจอร์ MVP'!$B:$B,$C10&"-*",'ฟีเจอร์ MVP'!$H:$H,"Should*") -> 1 | G10: =COUNTIFS('ฟีเจอร์ MVP'!$B:$B,$C10&"-*",'ฟีเจอร์ MVP'!$H:$H,"Could*") -> 0 | H10: =COUNTIFS('ฟีเจอร์ MVP'!$B:$B,$C10&"-*",'ฟีเจอร์ MVP'!$I:$I,"P0") -> 0 | I10: =COUNTIFS('ฟีเจอร์ MVP'!$B:$B,$C10&"-*",'ฟีเจอร์ MVP'!$I:$I,"P1") -> 9 | J10: =COUNTIFS('ฟีเจอร์ MVP'!$B:$B,$C10&"-*",'ฟีเจอร์ MVP'!$L:$L,"เสร็จแล้ว") -> 9 | K10: =IFERROR(J10/D10,0) -> 1 | L10: =COUNTIFS('ฟีเจอร์ MVP'!$B:$B,$C10&"-*",'ฟีเจอร์ MVP'!$L:$L,"กำลังทำ") -> 0 | M10: =COUNTIFS('ฟีเจอร์ MVP'!$B:$B,$C10&"-*",'ฟีเจอร์ MVP'!$L:$L,"ยังไม่เริ่ม") -> 0
A11: M10 | B11: ระบบหลังบ้าน | C11: FR-ADM | D11: =COUNTIFS('ฟีเจอร์ MVP'!$B:$B,$C11&"-*") -> 17 | E11: =COUNTIFS('ฟีเจอร์ MVP'!$B:$B,$C11&"-*",'ฟีเจอร์ MVP'!$H:$H,"Must*") -> 13 | F11: =COUNTIFS('ฟีเจอร์ MVP'!$B:$B,$C11&"-*",'ฟีเจอร์ MVP'!$H:$H,"Should*") -> 3 | G11: =COUNTIFS('ฟีเจอร์ MVP'!$B:$B,$C11&"-*",'ฟีเจอร์ MVP'!$H:$H,"Could*") -> 1 | H11: =COUNTIFS('ฟีเจอร์ MVP'!$B:$B,$C11&"-*",'ฟีเจอร์ MVP'!$I:$I,"P0") -> 1 | I11: =COUNTIFS('ฟีเจอร์ MVP'!$B:$B,$C11&"-*",'ฟีเจอร์ MVP'!$I:$I,"P1") -> 16 | J11: =COUNTIFS('ฟีเจอร์ MVP'!$B:$B,$C11&"-*",'ฟีเจอร์ MVP'!$L:$L,"เสร็จแล้ว") -> 9 | K11: =IFERROR(J11/D11,0) -> 0.52941176 | L11: =COUNTIFS('ฟีเจอร์ MVP'!$B:$B,$C11&"-*",'ฟีเจอร์ MVP'!$L:$L,"กำลังทำ") -> 8 | M11: =COUNTIFS('ฟีเจอร์ MVP'!$B:$B,$C11&"-*",'ฟีเจอร์ MVP'!$L:$L,"ยังไม่เริ่ม") -> 0
A12: M11 | B12: พื้นที่ทำงานองค์กร | C12: FR-ORG | D12: =COUNTIFS('ฟีเจอร์ MVP'!$B:$B,$C12&"-*") -> 11 | E12: =COUNTIFS('ฟีเจอร์ MVP'!$B:$B,$C12&"-*",'ฟีเจอร์ MVP'!$H:$H,"Must*") -> 11 | F12: =COUNTIFS('ฟีเจอร์ MVP'!$B:$B,$C12&"-*",'ฟีเจอร์ MVP'!$H:$H,"Should*") -> 0 | G12: =COUNTIFS('ฟีเจอร์ MVP'!$B:$B,$C12&"-*",'ฟีเจอร์ MVP'!$H:$H,"Could*") -> 0 | H12: =COUNTIFS('ฟีเจอร์ MVP'!$B:$B,$C12&"-*",'ฟีเจอร์ MVP'!$I:$I,"P0") -> 0 | I12: =COUNTIFS('ฟีเจอร์ MVP'!$B:$B,$C12&"-*",'ฟีเจอร์ MVP'!$I:$I,"P1") -> 11 | J12: =COUNTIFS('ฟีเจอร์ MVP'!$B:$B,$C12&"-*",'ฟีเจอร์ MVP'!$L:$L,"เสร็จแล้ว") -> 2 | K12: =IFERROR(J12/D12,0) -> 0.18181818 | L12: =COUNTIFS('ฟีเจอร์ MVP'!$B:$B,$C12&"-*",'ฟีเจอร์ MVP'!$L:$L,"กำลังทำ") -> 9 | M12: =COUNTIFS('ฟีเจอร์ MVP'!$B:$B,$C12&"-*",'ฟีเจอร์ MVP'!$L:$L,"ยังไม่เริ่ม") -> 0
A13: M12 | B13: ตรวจสัญญา | C13: FR-CR | D13: =COUNTIFS('ฟีเจอร์ MVP'!$B:$B,$C13&"-*") -> 6 | E13: =COUNTIFS('ฟีเจอร์ MVP'!$B:$B,$C13&"-*",'ฟีเจอร์ MVP'!$H:$H,"Must*") -> 6 | F13: =COUNTIFS('ฟีเจอร์ MVP'!$B:$B,$C13&"-*",'ฟีเจอร์ MVP'!$H:$H,"Should*") -> 0 | G13: =COUNTIFS('ฟีเจอร์ MVP'!$B:$B,$C13&"-*",'ฟีเจอร์ MVP'!$H:$H,"Could*") -> 0 | H13: =COUNTIFS('ฟีเจอร์ MVP'!$B:$B,$C13&"-*",'ฟีเจอร์ MVP'!$I:$I,"P0") -> 0 | I13: =COUNTIFS('ฟีเจอร์ MVP'!$B:$B,$C13&"-*",'ฟีเจอร์ MVP'!$I:$I,"P1") -> 6 | J13: =COUNTIFS('ฟีเจอร์ MVP'!$B:$B,$C13&"-*",'ฟีเจอร์ MVP'!$L:$L,"เสร็จแล้ว") -> 3 | K13: =IFERROR(J13/D13,0) -> 0.5 | L13: =COUNTIFS('ฟีเจอร์ MVP'!$B:$B,$C13&"-*",'ฟีเจอร์ MVP'!$L:$L,"กำลังทำ") -> 3 | M13: =COUNTIFS('ฟีเจอร์ MVP'!$B:$B,$C13&"-*",'ฟีเจอร์ MVP'!$L:$L,"ยังไม่เริ่ม") -> 0
A14: รวม | B14: ทุกโมดูล | D14: =SUM(D5:D13) -> 130 | E14: =SUM(E5:E13) -> 97 | F14: =SUM(F5:F13) -> 31 | G14: =SUM(G5:G13) -> 2 | H14: =SUM(H5:H13) -> 7 | I14: =SUM(I5:I13) -> 123 | J14: =SUM(J5:J13) -> 77 | K14: =IFERROR(J14/D14,0) -> 0.59230769 | L14: =SUM(L5:L13) -> 53 | M14: =SUM(M5:M13) -> 0
A16: ความคืบหน้าตามสถานะ
A17: สถานะ | B17: จำนวน
A18: ยังไม่เริ่ม | B18: =COUNTIF('ฟีเจอร์ MVP'!$L:$L,A18) -> 0
A19: กำลังทำ | B19: =COUNTIF('ฟีเจอร์ MVP'!$L:$L,A19) -> 53
A20: รอตรวจ | B20: =COUNTIF('ฟีเจอร์ MVP'!$L:$L,A20) -> 0
A21: เสร็จแล้ว | B21: =COUNTIF('ฟีเจอร์ MVP'!$L:$L,A21) -> 77
A22: เลื่อนออก | B22: =COUNTIF('ฟีเจอร์ MVP'!$L:$L,A22) -> 0
A23: รวม | B23: =SUM(B18:B22) -> 130
A25: วิธีใช้ไฟล์นี้
A26: • ชีต “ฟีเจอร์ MVP” = ฟีเจอร์ทั้งหมดที่ต้องมีในเฟส P0 + P1 ตาม docs/02-srs.md (เปิดทดลองใช้ในกลุ่มองค์กรนำร่อง) เรียงตามโมดูล
A27: • “สถานะ” และ “หมายเหตุ” ตรวจเทียบโค้ดและหน้าจอจริง ณ 1 ต.ค. 2569: เสร็จแล้ว = ผ่านเกณฑ์ตรวจรับครบทุกข้อ, กำลังทำ = ทำแล้วบางส่วน, ยังไม่เริ่ม = ยังไม่มีในระบบ; หมายเหตุบอกสิ่งที่ยังขาด
A28: • ช่องพื้นเหลือง (สถานะ, ผู้รับผิดชอบ, Sprint เป้าหมาย, หมายเหตุ) ทีมแก้ได้เอง — ช่องอื่นมาจาก SRS ห้ามแก้ที่นี่ ให้แก้ใน docs/02-srs.md
A29: • สถานะเลือกจาก dropdown: ยังไม่เริ่ม / กำลังทำ / รอตรวจ / เสร็จแล้ว / เลื่อนออก — ตารางสรุปด้านบนนับให้อัตโนมัติ
A30: • Must = ต้องมีก่อนเปิดใช้, Should = ควรมี (ตัดได้ถ้าเวลาไม่พอ), Could = ถ้ามีเวลา
A31: • P0 = งานวางฐานระบบ, P1 = ฟีเจอร์ MVP
A32: • ชีต “ข้อกำหนดคุณภาพ (NFR)” และ “กฎธุรกิจ (BR)” ใช้กับทุกฟีเจอร์ใน MVP; ชีต “หลังเฟส MVP” คือฟีเจอร์ที่ไม่อยู่ใน SRS ฉบับปัจจุบัน (เฟส 2–3) ยังไม่ทำตอนนี้

Sheet ฟีเจอร์ MVP
A1: ฟีเจอร์ MVP ทั้งหมด (เฟส P0 + P1)
A2: 130 ฟีเจอร์ · ที่มา docs/02-srs.md ฉบับ 1.8 (1 ต.ค. 2569) · สถานะและหมายเหตุตรวจเทียบโค้ดและหน้าจอจริง ณ 1 ต.ค. 2569 · ช่องพื้นเหลืองให้ทีมกรอก
A4: ลำดับ | B4: รหัส | C4: โมดูล | D4: ชื่อโมดูล | E4: ฟีเจอร์ | F4: รายละเอียด | G4: ผู้ใช้ที่เกี่ยวข้อง | H4: ความสำคัญ | I4: เฟส | J4: เกณฑ์ตรวจรับ (Acceptance Criteria) | K4: จำนวนเกณฑ์ | L4: สถานะ | M4: ผู้รับผิดชอบ | N4: Sprint เป้าหมาย | O4: หมายเหตุ
A5: 1 | B5: FR-AUTH-001 | C5: M1 | D5: บัญชีผู้ใช้และการเข้าถึง | E5: สมัครสมาชิกด้วยอีเมล | F5: ระบบต้องให้ผู้ใช้สมัครด้วยอีเมล + รหัสผ่าน + ชื่อที่แสดง และยืนยันอีเมลผ่านลิงก์ (อายุลิงก์ 24 ชม.) | G5: guest | H5: Must (ต้องมี) | I5: P1 | J5: AC1: Given ผู้ใช้อยู่แท็บ "สมัครสมาชิก" ในหน้า /login หรือหน้า /register When กรอกอีเมลที่ยังไม่ถูกใช้ + รหัสผ่านตาม BR-016 + ติ๊กยอมรับข้อกำหนดและ consent บริการหลัก Then ระบบสร้างบัญชีสถานะ pending_verification และส่งอีเมลยืนยัน AC2: Given อีเมลถูกใช้แล้ว When กดสมัคร Then แสดงข้อความกลาง ๆ "หากอีเมลนี้ยังไม่ได้ลงทะเบียน ระบบได้ส่งลิงก์ยืนยันไปแล้ว" (ไม่เปิดเผยว่ามีบัญชีอยู่) AC3: Given ผู้ใช้คลิกลิงก์ยืนยันภายใน 24 ชม. When เปิดลิงก์ Then บัญชีเป็น active และเข้าสู่ระบบอัตโนมัติ; ถ้าเกิน 24 ชม. แสดงปุ่ม "ส่งลิงก์ใหม่" | K5: 3 | L5: กำลังทำ | O5: ยังไม่ได้ใช้สถานะรอยืนยัน ไม่มีปุ่มส่งลิงก์ใหม่เมื่อลิงก์หมดอายุ และการยืนยันอีเมลใช้จริงได้เมื่อมี SMTP จริงเท่านั้น
A6: 2 | B6: FR-AUTH-002 | C6: M1 | D6: บัญชีผู้ใช้และการเข้าถึง | E6: เข้าสู่ระบบ | F6: ระบบต้องให้ผู้ใช้เข้าสู่ระบบด้วยอีเมล + รหัสผ่าน, มีปุ่มแสดง/ซ่อนรหัสผ่าน และตัวเลือกภาษา/ธีมบนหน้า login (ตาม AI-EDW) | G6: guest | H6: Must (ต้องมี) | I6: P0 | J6: AC1: Given บัญชี active When กรอกข้อมูลถูกต้อง Then สร้าง session ใหม่ (Better Auth ออก session token ใหม่ใน cookie lc.session_token) และ redirect ไป /chat หรือ URL ที่ขอไว้ก่อน login AC2: Given ข้อมูลผิด When กดเข้าสู่ระบบ Then แสดง "อีเมลหรือรหัสผ่านไม่ถูกต้อง" โดยไม่ระบุว่าผิดส่วนใด AC3: Given บัญชี pending_verification When login Then แจ้งให้ยืนยันอีเมลพร้อมปุ่มส่งลิงก์ใหม่ | K6: 3 | L6: กำลังทำ | O6: เข้าสู่ระบบด้วยบัญชีที่ยังไม่ยืนยันได้ข้อความแจ้งและระบบส่งลิงก์ให้เอง แต่ไม่มีปุ่ม "ส่งลิงก์ใหม่" ในหน้าเข้าสู่ระบบ
A7: 3 | B7: FR-AUTH-003 | C7: M1 | D7: บัญชีผู้ใช้และการเข้าถึง | E7: จดจำการเข้าสู่ระบบ (Remember me) | F7: ระบบต้องมีตัวเลือก "จดจำฉัน" ที่คง session ได้ตาม BR-017 | G7: guest | H7: Should (ควรมี) | I7: P1 | J7: AC1: Given ติ๊ก "จดจำฉัน" When ปิดเบราว์เซอร์แล้วเปิดใหม่ภายในระยะที่กำหนด Then ยังอยู่ในระบบ | K7: 1 | L7: เสร็จแล้ว
A8: 4 | B8: FR-AUTH-004 | C8: M1 | D8: บัญชีผู้ใช้และการเข้าถึง | E8: ลืมรหัสผ่าน | F8: ระบบต้องให้ผู้ใช้ขอลิงก์ตั้งรหัสผ่านใหม่ทางอีเมล (ลิงก์ใช้ครั้งเดียว อายุ 1 ชม.) และยกเลิก session อื่นทั้งหมดหลังตั้งรหัสใหม่ | G8: guest | H8: Must (ต้องมี) | I8: P1 | J8: AC1: Given ผู้ใช้กรอกอีเมลใด ๆ When กดส่ง Then แสดงข้อความเดียวกันเสมอ (ไม่เปิดเผยการมีอยู่ของบัญชี) AC2: Given ลิงก์ถูกใช้แล้วหรือหมดอายุ When เปิดลิงก์ Then แสดงว่าลิงก์ใช้ไม่ได้ AC3: Given ตั้งรหัสใหม่สำเร็จ When มี session อื่นเปิดอยู่ Then session เหล่านั้นถูกยกเลิกและบันทึก audit log | K8: 3 | L8: กำลังทำ | O8: ลืมรหัสผ่านซ่อนอยู่ (หน้า 404) จนกว่าจะตั้ง SMTP จริง (MAIL_LIVE) ผู้ใช้จึงยังขอลิงก์ตั้งรหัสใหม่ไม่ได้ในระบบทดสอบ
A9: 5 | B9: FR-AUTH-005 | C9: M1 | D9: บัญชีผู้ใช้และการเข้าถึง | E9: ออกจากระบบ | F9: ระบบต้องให้ออกจากระบบจาก user menu โดยทำลาย session ฝั่ง server และล้าง cookie | G9: member+ | H9: Must (ต้องมี) | I9: P0 | J9: AC1: Given ผู้ใช้กด "ออกจากระบบ" When redirect ไป /login Then การเรียก API ด้วย session เดิมได้ HTTP 401 | K9: 1 | L9: เสร็จแล้ว
A10: 6 | B10: FR-AUTH-006 | C10: M1 | D10: บัญชีผู้ใช้และการเข้าถึง | E10: โหมด Guest | F10: ระบบต้องให้ผู้ใช้เริ่มใช้งานแชทและอ่านเนื้อหาได้โดยไม่สมัคร ผ่านปุ่ม "ทดลองใช้โดยไม่สมัคร" (สร้าง guest identity ด้วย Better Auth anonymous plugin เป็นแถว app.users ที่ is_anonymous = true และใช้ cookie session ปกติ) | G10: guest | H10: Must (ต้องมี) | I10: P1 | J10: AC1: Given ผู้ใช้กด "ทดลองใช้โดยไม่สมัคร" และยอมรับ consent บริการหลัก When เข้าสู่ /chat Then แชทได้ และ sidebar แสดงแชทของ guest นั้น AC2: Given guest When เปิดเมนูที่ต้องเป็นสมาชิก (ที่บันทึกไว้, แชร์แชท, โฟลเดอร์แชท, องค์กร) Then แสดง prompt ชวนสมัคร/เข้าสู่ระบบ AC3: Given guest ไม่ได้ใช้งานเกินระยะใน BR-003 Then ข้อมูลแชทของ guest ถูกลบโดย job - หมายเหตุ (สิ่งที่เห็นบนหน้าจอ): ชื่อผู้ใช้ของ guest คือ "ผู้ทดลองใช้" และข้อความต้อนรับไม่มีชื่อ; ปุ่ม "ทดลองใช้โดยไม่สมัคร (ถามได้ 10 ข้อความต่อวัน)" อยู่ในหน้าเข้าสู่ระบบและหน้าสมัครสมาชิก; แถบซ้ายมีลิงก์ "สมัครสมาชิกเพื่อบันทึกประวัติ"; "ที่บันทึกไว้" แสดง "ผู้ใช้ทดลองบันทึกคำตอบไม่ได้ สมัครสมาชิกเพื่อเก็บคำตอบและบทความไว้ดูภายหลัง" พร้อมปุ่ม "สมัครสมาชิก"; "ตั้งค่าบัญชี" มีเฉพาะการ์ด "การแสดงผล" (ภาษา ธีม ขนาดตัวอักษร เก็บในเบราว์เซอร์นี้) กับข้อความชวนสมัครสมาชิก; ตัวสลับพื้นที่ทำงานแสดง "สมัครสมาชิกก่อนเพื่อสร้างพื้นที่ทำงานองค์กร" และเมนู "องค์กร" ไม่ปรากฏ | K10: 3 | L10: เสร็จแล้ว
A11: 7 | B11: FR-AUTH-007 | C11: M1 | D11: บัญชีผู้ใช้และการเข้าถึง | E11: Quota ของ Guest และแบนเนอร์แจ้งเตือน | F11: ระบบต้องจำกัดจำนวนข้อความต่อวันตาม role (BR-001) และแสดงจำนวนที่เหลือเมื่อเหลือ ≤ 3 ข้อความ | G11: all | H11: Must (ต้องมี) | I11: P1 | J11: AC1: Given guest ใช้ครบ quota When ส่งข้อความ Then ได้ SSE event guardrail (kind=quota, stage=quota) และ bubble แจ้ง "ใช้ครบโควตาวันนี้แล้ว" พร้อมปุ่มสมัครสมาชิก AC2: Given เหลือ 3 ข้อความ When ส่งข้อความ Then แสดงแบนเนอร์เหนือช่องพิมพ์ "เหลือ 3 ข้อความสำหรับวันนี้" AC3: Given เวลา 00:00 Asia/Bangkok When เริ่มวันใหม่ Then quota รีเซ็ต | K11: 3 | L11: เสร็จแล้ว
A12: 8 | B12: FR-AUTH-008 | C12: M1 | D12: บัญชีผู้ใช้และการเข้าถึง | E12: ย้ายแชท Guest เข้าบัญชี | F12: ระบบต้องย้ายแชทของ guest เข้าบัญชีโดยอัตโนมัติเมื่อ guest สมัครสมาชิกหรือเข้าสู่ระบบในเบราว์เซอร์เดียวกัน (claim_guest_data) | G12: guest → member | H12: Should (ควรมี) | I12: P1 | J12: AC1: Given guest มีแชท ≥1 When สมัคร/login สำเร็จ Then แชทเปลี่ยน owner เป็น user และ guest identity ถูกปิด | K12: 1 | L12: กำลังทำ | O12: ยังไม่มีการทดสอบการย้ายแชท guest เข้าบัญชี และอาจไม่ทำงานเมื่อเปิดบังคับยืนยันอีเมลก่อนเข้าระบบ
A13: 9 | B13: FR-AUTH-009 | C13: M1 | D13: บัญชีผู้ใช้และการเข้าถึง | E13: PDPA Consent แยกวัตถุประสงค์ | F13: ระบบต้องขอ consent แยกตามวัตถุประสงค์ (enum app.consent_purpose): (1) service_terms ข้อตกลงการใช้บริการ (จำเป็น) + privacy_notice รับทราบประกาศความเป็นส่วนตัว (จำเป็น) (2) improve_service ใช้ข้อมูลแบบไม่ระบุตัวตนเพื่อปรับปรุงระบบ (opt-in) (3) marketing (opt-in) พร้อมลิงก์ประกาศความเป็นส่วนตัวเวอร์ชันปัจจุบัน | G13: all | H13: Must (ต้องมี) | I13: P1 | J13: AC1: Given ผู้ใช้ใหม่ When สมัคร/เริ่ม guest Then ต้องยอมรับ service_terms + privacy_notice ก่อนใช้งาน; improve_service ไม่ติ๊กไว้ล่วงหน้า AC2: Given consent ถูกให้หรือถอน When บันทึก Then เก็บ record ใน app.user_consents พร้อม purpose, version ประกาศ, timestamp, IP hash AC3: Given ประกาศความเป็นส่วนตัวมีเวอร์ชันใหม่ที่ต้องขอ consent ใหม่ When ผู้ใช้เข้าระบบครั้งถัดไป Then แสดง dialog ขอ consent ใหม่ | K13: 3 | L13: กำลังทำ | O13: ยังไม่มีช่องขอความยินยอมแบบเลือก (ปรับปรุงระบบ/การตลาด) ในหน้าสมัคร/หน้ายอมรับ มีเฉพาะข้อกำหนดและประกาศความเป็นส่วนตัว
A14: 10 | B14: FR-AUTH-010 | C14: M1 | D14: บัญชีผู้ใช้และการเข้าถึง | E14: ถอน Consent | F14: ระบบต้องให้ผู้ใช้ดูและถอน consent ได้จากเมนู "ความเป็นส่วนตัว & ข้อมูลของฉัน" | G14: member+ | H14: Must (ต้องมี) | I14: P1 | J14: AC1: Given ผู้ใช้ถอน consent ที่ไม่บังคับ (improve_service, marketing) When ยืนยัน Then มีผลทันที และบันทึก record ถอนใน app.user_consents AC2: Given ผู้ใช้ถอน service_terms Then ระบบแจ้งว่าต้องลบบัญชี และนำไปขั้นตอน FR-AUTH-018 | K14: 2 | L14: กำลังทำ | O14: หน้าตั้งค่าแสดงเฉพาะความยินยอมที่บังคับ ยังไม่มีปุ่มถอนความยินยอมที่ไม่บังคับ (ปรับปรุงระบบ/การตลาด) มีแต่ข้อความให้ลบบัญชี
A15: 11 | B15: FR-AUTH-011 | C15: M1 | D15: บัญชีผู้ใช้และการเข้าถึง | E15: โปรไฟล์ | F15: ระบบต้องให้แก้ชื่อที่แสดงจากหน้าตั้งค่าบัญชี (/settings) | G15: member+ | H15: Should (ควรมี) | I15: P1 | J15: AC1: Given แก้ชื่อแล้วบันทึก Then ชื่อใน header และเมนูผู้ใช้อัปเดต | K15: 1 | L15: เสร็จแล้ว
A16: 12 | B16: FR-AUTH-012 | C16: M1 | D16: บัญชีผู้ใช้และการเข้าถึง | E16: เปลี่ยนรหัสผ่าน | F16: ระบบต้องให้เปลี่ยนรหัสผ่านโดยกรอกรหัสปัจจุบัน + รหัสใหม่ 2 ครั้ง | G16: member+ | H16: Must (ต้องมี) | I16: P1 | J16: AC1: Given รหัสปัจจุบันผิด Then ไม่เปลี่ยนและนับเป็นความพยายามล้มเหลว (FR-AUTH-019) AC2: Given สำเร็จ Then session อื่นทั้งหมดถูกยกเลิก และส่งอีเมลแจ้งเตือนการเปลี่ยนรหัส | K16: 2 | L16: กำลังทำ | O16: ฟอร์มเปลี่ยนรหัสผ่านมีช่องรหัสปัจจุบันและรหัสใหม่ แต่ยังไม่มีช่องกรอกรหัสใหม่ซ้ำครั้งที่สอง
A17: 13 | B17: FR-AUTH-013 | C17: M1 | D17: บัญชีผู้ใช้และการเข้าถึง | E17: เลือกภาษา | F17: ระบบต้องให้เลือกภาษา UI (ไทย, English) จากปุ่มภาษาใน header และหน้า login; บันทึกใน profile (member) หรือ localStorage (guest) | G17: all | H17: Must (ต้องมี) | I17: P0 | J17: AC1: Given เลือก English When หน้า reload Then ข้อความ UI ทั้งหมดเป็นภาษาอังกฤษ และ <html lang="en"> AC2: Given ภาษา UI = English Then ข้อความของระบบในคำตอบ (คำนำ บรรทัดปิดท้าย) เป็นภาษาอังกฤษ และเนื้อหาจากคลังเป็นภาษาไทย (FR-AI-018) | K17: 2 | L17: เสร็จแล้ว
A18: 14 | B18: FR-AUTH-014 | C18: M1 | D18: บัญชีผู้ใช้และการเข้าถึง | E18: ธีม Light/Dark | F18: ระบบต้องมี toggle ธีม, ใช้ค่าจาก prefers-color-scheme เมื่อยังไม่เคยเลือก, ใช้ธีมก่อน first paint (ไม่กระพริบ) และจำใน localStorage key lc_theme | G18: all | H18: Must (ต้องมี) | I18: P0 | J18: AC1: Given เลือก dark When เปิดหน้าใดก็ตาม Then ไม่มีการกระพริบเป็นสีขาวก่อน render AC2: ทุก component ผ่าน contrast ตาม NFR-A11Y-002 ทั้ง 2 ธีม | K18: 2 | L18: เสร็จแล้ว
A19: 15 | B19: FR-AUTH-016 | C19: M1 | D19: บัญชีผู้ใช้และการเข้าถึง | E19: Session Countdown และหมดอายุ | F19: ระบบต้องแสดงเวลาที่เหลือของ session ที่ footer (ตาม AI-EDW), เตือนเมื่อเหลือ 5 นาที พร้อมปุ่ม "ต่อเวลา" แล้วออกจากระบบอัตโนมัติเมื่อหมดเวลา และเรียก check_session เป็นระยะ | G19: member+ | H19: Should (ควรมี) | I19: P1 | J19: AC1: Given เหลือ 5 นาที Then แสดง toast พร้อมปุ่ม "ต่อเวลา"; กดแล้ว countdown รีเซ็ต AC2: Given session หมดอายุ When ผู้ใช้กดส่งข้อความ Then ข้อความที่พิมพ์ถูกเก็บเป็น draft ใน sessionStorage (ต่อแท็บ — ไม่ใช้ localStorage เพื่อไม่ให้ข้อความคดีค้างในเครื่องที่ใช้ร่วมกัน) และ redirect ไป login; กลับมาแล้วข้อความยังอยู่ (ล้างเมื่อกดออกจากระบบ) | K19: 2 | L19: กำลังทำ | O19: ยังไม่เปลี่ยนเส้นทางไปหน้าเข้าสู่ระบบเมื่อกดส่งข้อความตอนเซสชันหมดอายุ (ได้เพียงข้อความผิดพลาดและร่างถูกล้างตอนส่ง)
A20: 16 | B20: FR-AUTH-017 | C20: M1 | D20: บัญชีผู้ใช้และการเข้าถึง | E20: ส่งออกข้อมูลของฉัน | F20: ระบบต้องให้ผู้ใช้ดาวน์โหลดข้อมูลส่วนบุคคลของตนเป็นไฟล์ JSON ทันทีจากหน้าตั้งค่า (โปรไฟล์, ตั้งค่า, consent, แชท, feedback) | G20: member+ | H20: Must (ต้องมี) | I20: P1 | J20: AC1: Given ผู้ใช้กด "ดาวน์โหลดข้อมูลของฉัน" Then ได้ไฟล์ JSON ของบัญชีนั้น และมีรายการใน app.dsr_requests AC2: ต้อง login ด้วยบัญชีเดียวกันจึงดาวน์โหลดได้ | K20: 2 | L20: เสร็จแล้ว
A21: 17 | B21: FR-AUTH-018 | C21: M1 | D21: บัญชีผู้ใช้และการเข้าถึง | E21: ลบบัญชี | F21: ระบบต้องให้ลบบัญชีด้วยการยืนยันรหัสผ่าน โดยบัญชีเข้าสู่สถานะ pending_deletion ตาม BR-012 และยกเลิกได้ในช่วงผ่อนผัน | G21: member | H21: Must (ต้องมี) | I21: P1 | J21: AC1: Given ยืนยันลบ Then logout ทันที, ลิงก์แชร์ทั้งหมดถูก revoke, ส่งอีเมลยืนยันพร้อมลิงก์ยกเลิก AC2: Given พ้นช่วงผ่อนผัน Then job ลบข้อมูลส่วนบุคคลแบบถาวร และ audit log เก็บเฉพาะ user id แบบ pseudonymized | K21: 2 | L21: เสร็จแล้ว
A22: 18 | B22: FR-AUTH-019 | C22: M1 | D22: บัญชีผู้ใช้และการเข้าถึง | E22: ป้องกันการเดารหัสผ่าน | F22: ระบบต้องจำกัดความพยายาม login ล้มเหลวต่อบัญชีและต่อ IP ตาม BR-016 | G22: all | H22: Must (ต้องมี) | I22: P1 | J22: AC1: Given ล้มเหลว 5 ครั้งใน 15 นาที Then ล็อก 15 นาที และแจ้งเจ้าของบัญชีทางอีเมล AC2: ทุกเหตุการณ์ login (สำเร็จ/ล้มเหลว/ล็อก) ถูกบันทึกใน app.audit_log | K22: 2 | L22: เสร็จแล้ว
A23: 19 | B23: FR-AUTH-021 | C23: M1 | D23: บัญชีผู้ใช้และการเข้าถึง | E23: ตรวจเวอร์ชันแอป (Build check) | F23: ทุก JSON response ต้องมีฟิลด์ build; เมื่อ client พบ build ต่างจากที่โหลดไว้ ต้องแสดงแถบ "มีเวอร์ชันใหม่ — รีเฟรช" (ตาม AI-EDW) | G23: all | H23: Should (ควรมี) | I23: P0 | J23: AC1: Given deploy build ใหม่ When client เรียก API ครั้งถัดไป Then แสดงแถบแจ้งเตือน (ไม่ reload เองขณะกำลัง stream) | K23: 1 | L23: เสร็จแล้ว
A24: 20 | B24: FR-AUTH-022 | C24: M1 | D24: บัญชีผู้ใช้และการเข้าถึง | E24: Role-based Access Control | F24: ระบบต้องบังคับสิทธิ์ตาม role (guest, member, editor, reviewer, admin) ที่ฝั่ง server ทุก action และตรวจ ownership ของ resource; role ที่ได้จากสคริปต์ scripts/set-role.sh หรือหน้า "ผู้ใช้" ของหลังบ้าน | G24: all | H24: Must (ต้องมี) | I24: P0 | J24: AC1: Given member เรียก admin_* action Then ได้ HTTP 403 และบันทึก audit log AC2: Given user A ขอ get_chat ของ user B Then ได้ HTTP 404 (ไม่เปิดเผยการมีอยู่) AC3: ผู้ใช้ 1 คนมี role ระบบได้ 1 role (enum app.user_role); ผู้ที่ส่งเนื้อหาเข้าตรวจล่าสุดอนุมัติเนื้อหานั้นเองไม่ได้ (BR-007) | K24: 3 | L24: เสร็จแล้ว
A25: 21 | B25: FR-AUTH-023 | C25: M1 | D25: บัญชีผู้ใช้และการเข้าถึง | E25: ขนาดตัวอักษร (Text Scale) | F25: ระบบต้องให้ผู้ใช้เลือกขนาดตัวอักษรของเนื้อหา (app.user_settings.text_scale: 100% / 112% / 125% / 150% ตาม CHECK ใน DB) จากหน้าตั้งค่า เพื่อรองรับผู้สูงอายุ; guest เก็บในเบราว์เซอร์ (cookie lc_scale) | G25: all | H25: Should (ควรมี) | I25: P1 | J25: AC1: Given เลือก 125% Then ข้อความแชท บทความ และคู่มือขยายทันทีโดย layout ไม่แตก (สอดคล้อง NFR-A11Y-006) และค่าคงอยู่หลัง reload/login ใหม่ AC2: บันทึกผ่าน update_settings (member) และมีผลกับทุกอุปกรณ์ของบัญชีนั้น | K25: 2 | L25: เสร็จแล้ว
A26: 22 | B26: FR-AUTH-024 | C26: M1 | D26: บัญชีผู้ใช้และการเข้าถึง | E26: ติดตามคำขอใช้สิทธิเจ้าของข้อมูล (DSR) | F26: ทุกคำขอตามสิทธิ PDPA (เข้าถึง/ขอสำเนา, แก้ไข, ลบ, คัดค้าน, ถอน consent) ต้องสร้างรายการใน app.dsr_requests (request_type: access, export, rectify, erase, object, withdraw_consent) พร้อม due_at = วันรับคำขอ + 30 วัน และผู้ใช้เห็นสถานะคำขอของตนในหน้า "ความเป็นส่วนตัว & ข้อมูลของฉัน" | G26: member | H26: Must (ต้องมี) | I26: P1 | J26: AC1: Given ผู้ใช้ใช้ privacy_export Then มีแถวใน app.dsr_requests ประเภท export สถานะ completed ทันที; Given ใช้ request_account_deletion Then มีแถวประเภท erase สถานะ in_progress และได้อีเมลยืนยันพร้อมลิงก์ยกเลิก AC2: สถานะเปลี่ยนตามลำดับ received → in_progress → completed | rejected; การปฏิเสธต้องมีเหตุผลที่แจ้งผู้ใช้ AC3: คำขอที่ใกล้ครบ due_at (≤ 7 วัน) ถูกแจ้งเตือนผู้ดูแล (FR-ADM-023) — SLA 30 วันตาม NFR-PRIV-006 | K26: 3 | L26: กำลังทำ | O26: ผู้ใช้เห็นสถานะคำขอ แต่ยังไม่เห็นเหตุผลเมื่อคำขอถูกปฏิเสธ และการถอนความยินยอมยังไม่สร้างรายการคำขอ
A27: 23 | B27: FR-AUTH-025 | C27: M1 | D27: บัญชีผู้ใช้และการเข้าถึง | E27: ยืนยันตัวตนสองชั้นสำหรับเจ้าหน้าที่ (TOTP 2FA) | F27: บัญชีที่มี role editor, reviewer หรือ admin ต้องลงทะเบียน TOTP (Better Auth twoFactor plugin; secret เก็บแบบเข้ารหัสใน app.two_factors) และยืนยันรหัส 6 หลักทุกครั้งที่ login; มี recovery codes แบบใช้ครั้งเดียว | G27: editor, reviewer, admin | H27: Must (ต้องมี) | I27: P1 | J27: AC1: Given ผู้ใช้ได้รับ role staff ครั้งแรก When login Then ถูกบังคับเข้าหน้าตั้งค่า TOTP ก่อนเข้า /admin AC2: Given ใส่รหัส TOTP ผิด 5 ครั้ง Then ล็อกชั่วคราวตาม FR-AUTH-019 และบันทึก app.audit_log AC3: สอดคล้อง NFR-SEC-006; "จดจำฉัน" ใช้ไม่ได้กับ role staff (BR-017) | K27: 3 | L27: กำลังทำ | O27: ยังไม่ล็อกบัญชีและไม่บันทึก audit เมื่อใส่รหัส TOTP ผิด 5 ครั้ง (มีแค่จำกัดอัตรา 10 ครั้ง/15 นาที) และมีตัวเลือกเชื่อถืออุปกรณ์ 30 วัน
A28: 24 | B28: FR-CHAT-001 | C28: M2 | D28: แชทถามกฎหมาย (หน้าจอและการใช้งาน) | E28: เริ่มแชทใหม่และ Empty State | F28: ระบบต้องมีปุ่ม "แชทใหม่" ใน sidebar; หน้าแชทว่างต้องแสดงคำทักทาย, disclaimer สั้น และการ์ดตัวอย่างคำถาม 4 ใบที่ตรงกับเรื่องที่คลังความรู้ครอบคลุม (ค่าปรับส่งงานล่าช้า, ของไม่ได้มาตรฐาน, การเลิกสัญญา, ตรวจข้อสัญญา) | G28: all | H28: Must (ต้องมี) | I28: P1 | J28: AC1: Given ผู้ใช้กด "แชทใหม่" Then พื้นที่แชทว่าง, URL ไม่มี ?chat=, ช่องพิมพ์ได้ focus AC2: Given กดการ์ดตัวอย่าง Then ข้อความของการ์ดถูกส่งเป็นคำถามทันที AC3: แชทใหม่ยังไม่ถูกสร้างใน DB จนกว่าจะส่งข้อความแรก (server ส่ง event chat_id) | K28: 3 | L28: กำลังทำ | O28: เปิดแชทใหม่แล้วช่องพิมพ์ยังไม่ถูกโฟกัสอัตโนมัติ
A29: 25 | B29: FR-CHAT-002 | C29: M2 | D29: แชทถามกฎหมาย (หน้าจอและการใช้งาน) | E29: ส่งข้อความ | F29: ระบบต้องมีช่องพิมพ์แบบ auto-grow (ขยายตามข้อความจนถึงความสูงสูงสุดแล้ว scroll), Enter = ส่ง, Shift+Enter = ขึ้นบรรทัดใหม่, ตัวนับอักษรเมื่อใกล้ถึง BR-002 | G29: all | H29: Must (ต้องมี) | I29: P1 | J29: AC1: Given ข้อความว่างหรือมีแต่ช่องว่าง Then ปุ่มส่ง disabled AC2: Given ข้อความเกิน BR-002 Then ส่งไม่ได้และแสดงจำนวนอักษรเกิน AC3: Given ส่งแล้ว Then bubble ผู้ใช้ปรากฏทันที และ bubble ผู้ช่วยแสดงสถานะ "กำลังวิเคราะห์คำถาม…" AC4: ระหว่างกำลัง stream ในแชทเดียวกัน ปุ่มส่งเปลี่ยนเป็นปุ่ม "หยุด" (FR-CHAT-005) | K29: 4 | L29: เสร็จแล้ว
A30: 26 | B30: FR-CHAT-003 | C30: M2 | D30: แชทถามกฎหมาย (หน้าจอและการใช้งาน) | E30: แสดงคำตอบแบบ Streaming | F30: ระบบต้องแสดงคำตอบทีละส่วนจาก SSE event chunk พร้อม fade-in เฉพาะส่วนที่เพิ่มใหม่ และ render markdown แบบปลอดภัยระหว่าง stream | G30: all | H30: Must (ต้องมี) | I30: P1 | J30: AC1: Given คำตอบกำลัง stream When ผู้ใช้ไม่ได้เลื่อนขึ้น Then หน้าจอเลื่อนตามอัตโนมัติ; When ผู้ใช้เลื่อนขึ้น Then หยุดเลื่อนตามและแสดงปุ่ม scroll-to-bottom AC2: Given เครือข่ายขาดกลางคัน Then bubble แสดงข้อความ error ที่อ่านเข้าใจ + ปุ่ม "ลองใหม่" และเก็บส่วนที่ได้รับแล้ว AC3: TTFT เป็นไปตาม NFR-PERF-001 | K30: 3 | L30: กำลังทำ | O30: ยังไม่มี fade-in เฉพาะส่วนที่เพิ่มใหม่ และ TTFT ที่ 200 สตรีมพร้อมกันเกินเป้าเล็กน้อย (3.48 วินาที)
A31: 27 | B31: FR-CHAT-004 | C31: M2 | D31: แชทถามกฎหมาย (หน้าจอและการใช้งาน) | E31: แสดงสถานะขั้นตอนการทำงาน | F31: ระบบต้องแสดงข้อความสถานะจาก event status ใน header ของ bubble ผู้ช่วย (กระพริบเบา ๆ) เช่น "กำลังวิเคราะห์คำถาม", "กำลังค้นตัวบทกฎหมาย", "กำลังตรวจสอบการอ้างอิง" และล้างเมื่อ complete | G31: all | H31: Must (ต้องมี) | I31: P1 | J31: AC1: Given ได้ event status Then ข้อความสถานะแทนที่ข้อความก่อนหน้า (ไม่ต่อท้ายในเนื้อหา) AC2: Given prefers-reduced-motion Then ไม่มีการกระพริบ | K31: 2 | L31: เสร็จแล้ว
A32: 28 | B32: FR-CHAT-005 | C32: M2 | D32: แชทถามกฎหมาย (หน้าจอและการใช้งาน) | E32: หยุดการสร้างคำตอบ | F32: ระบบต้องให้กด "หยุด" เพื่อยกเลิก stream (AbortController) และ server ต้องหยุดประมวลผลคำตอบนั้นด้วย | G32: all | H32: Must (ต้องมี) | I32: P1 | J32: AC1: Given กดหยุด Then ส่วนที่ได้รับแล้วถูกเก็บพร้อมข้อความ "หยุดการสร้างคำตอบแล้ว" และมีปุ่มสร้างใหม่ AC2: ข้อความที่ถูกหยุดนับ quota ตามจริง (นับเมื่อเริ่มส่ง) | K32: 2 | L32: กำลังทำ | O32: ข้อความที่กดหยุดยังไม่มีปุ่มสร้างคำตอบใหม่ (ปุ่มแสดงเฉพาะคำตอบที่เสร็จสมบูรณ์)
A33: 29 | B33: FR-CHAT-006 | C33: M2 | D33: แชทถามกฎหมาย (หน้าจอและการใช้งาน) | E33: สร้างคำตอบใหม่ (Regenerate) | F33: ระบบต้องมีปุ่ม regenerate ที่คำตอบล่าสุดเท่านั้น ส่ง regenerate: 1 เพื่อแทนที่คำตอบล่าสุด; เก็บเวอร์ชันก่อนหน้าให้สลับดูได้ (‹ 1/2 ›) | G33: all | H33: Should (ควรมี) | I33: P1 | J33: AC1: Given กด regenerate Then คำตอบใหม่แทนที่ในตำแหน่งเดิม และมีตัวสลับเวอร์ชัน AC2: regenerate นับ quota 1 ข้อความ | K33: 2 | L33: เสร็จแล้ว
A34: 30 | B34: FR-CHAT-007 | C34: M2 | D34: แชทถามกฎหมาย (หน้าจอและการใช้งาน) | E34: คัดลอกข้อความ | F34: ระบบต้องมีปุ่มคัดลอกที่คำตอบของผู้ช่วย (คัดลอกข้อความของคำตอบเป็นข้อความธรรมดา) | G34: all | H34: Must (ต้องมี) | I34: P1 | J34: AC1: Given กดคัดลอก Then ไอคอนเปลี่ยนเป็นสถานะ "คัดลอกแล้ว" 1.5 วินาที และ clipboard มีข้อความของคำตอบ | K34: 1 | L34: เสร็จแล้ว
A35: 31 | B35: FR-CHAT-008 | C35: M2 | D35: แชทถามกฎหมาย (หน้าจอและการใช้งาน) | E35: Render Markdown อย่างปลอดภัย | F35: ระบบต้อง render markdown (หัวข้อ, list, ตาราง, ตัวหนา, blockquote, ลิงก์) ด้วย react-markdown + remark-gfm + rehype-sanitize (allow-list; ห้าม dangerouslySetInnerHTML กับข้อความดิบ); ลิงก์ภายนอกเปิดแท็บใหม่ rel="noopener noreferrer"; ตารางกว้างเลื่อนแนวนอนได้ และมีปุ่มคัดลอกตาราง | G35: all | H35: Must (ต้องมี) | I35: P1 | J35: AC1: Given ข้อความมี <script> หรือ onerror= Then ไม่ถูก execute (ทดสอบด้วย XSS payload list) AC2: Given ข้อความมี error Then แสดงเป็น textContent | K35: 2 | L35: กำลังทำ | O35: ยังไม่มีปุ่มคัดลอกตารางในคำตอบ
A36: 32 | B36: FR-CHAT-009 | C36: M2 | D36: แชทถามกฎหมาย (หน้าจอและการใช้งาน) | E36: Citation Chips | F36: ระบบต้องแสดง citation แบบตัวยก [1] ในเนื้อหา และแถบ chips ท้ายคำตอบ เช่น [1] ป.พ.พ. ม.420, [2] บทความ: ผิดสัญญาเช่า จาก event citations (chip แสดงเลขลำดับและชื่อแหล่ง) | G36: all | H36: Must (ต้องมี) | I36: P1 | J36: AC1: Given click chip หรือ [n] Then เปิด Source Drawer (FR-CHAT-010) ที่รายการนั้น AC2: Given คำตอบไม่มี citation (เช่น คำทักทาย) Then ไม่แสดงแถบ chips | K36: 2 | L36: เสร็จแล้ว
A37: 33 | B37: FR-CHAT-010 | C37: M2 | D37: แชทถามกฎหมาย (หน้าจอและการใช้งาน) | E37: Source Drawer (แผง "แหล่งอ้างอิง") | F37: ระบบต้องแสดงรายการแหล่งอ้างอิงของคำตอบที่เลือก; แต่ละรายการแสดงชนิดแหล่ง, ชื่อกฎหมาย/บทความ/เลขมาตรา, ข้อความของแหล่งนั้น (ตัวบทแสดงตามวรรค), วันที่ของข้อมูล (as-of), วันมีผล (ถ้ามี), ปุ่ม "เปิดดูฉบับเต็ม" ไปหน้า /law/... / /library/... และลิงก์แหล่งต้นฉบับทางการ (ถ้ามี) — ข้อมูลมากับ event citations ไม่ต้องเรียก endpoint เพิ่ม | G37: all | H37: Must (ต้องมี) | I37: P1 | J37: AC1: Given เปิด drawer บนมือถือ Then แสดงเป็น bottom sheet ปิดด้วยปุ่มปิดหรือกด Esc (บนเดสก์ท็อปเป็นแผงด้านขวา) AC2: Given เปิดจาก chip หรือ [n] Then เลื่อนไปที่รายการนั้นและเน้นกรอบ | K37: 2 | L37: เสร็จแล้ว
A38: 34 | B38: FR-CHAT-011 | C38: M2 | D38: แชทถามกฎหมาย (หน้าจอและการใช้งาน) | E38: ขอบเขตกฎหมาย (Legal Scope Selector) | F38: ระบบต้องมีแผง "ขอบเขตกฎหมาย" เหนือช่องพิมพ์ แสดง เฉพาะหมวดที่มีเนื้อหาในคลังความรู้ (checkbox) + ตัวเลือก "อัตโนมัติ" (ค่าเริ่มต้น) + "เลือกทั้งหมด" + พับ/ขยายได้; ค่าที่เลือกผูกกับแชทนั้น (หน้าจอแสดงชิป "ขอบเขตกฎหมาย: อัตโนมัติ" เมื่อกดเปิดแผงจะมีข้อความ "ถ้าเลือก คำตอบจะค้นเฉพาะหมวดที่เลือก" และช่องติ๊ก 3 หมวด: "บุคคลและนิติกรรม", "หนี้และสัญญา", "กระบวนการยุติธรรมและวิธีพิจารณาความ" — ยังไม่มี "คุ้มครองผู้บริโภค" ในรายการนี้ทั้งที่หน้า "คลังความรู้" มี 4 หมวด) | G38: all | H38: Should (ควรมี) | I38: P1 | J38: AC1: Given เลือก "อัตโนมัติ" Then request ส่ง scope: "auto" และระบบจัดหมวดเอง AC2: Given เลือกหมวดที่มีเนื้อหา (เช่น CONTRACT) Then request ส่ง scope: ["CONTRACT"] และการ retrieve จำกัดเฉพาะหมวดนั้น (ตรวจจาก log citations) AC3: Given เปลี่ยนแชท Then แผงแสดง scope ของแชทนั้น | K38: 3 | L38: เสร็จแล้ว
A39: 35 | B39: FR-CHAT-013 | C39: M2 | D39: แชทถามกฎหมาย (หน้าจอและการใช้งาน) | E39: คำถามต่อเนื่องแนะนำ (Follow-up Suggestions) | F39: ระบบต้องแสดงคำถามต่อเนื่องแนะนำไม่เกิน 3 ข้อใต้คำตอบล่าสุด (ฟิลด์ followups ของ event suggestions) | G39: all | H39: Should (ควรมี) | I39: P1 | J39: AC1: Given คำตอบเสร็จ Then แสดง suggestion 0–3 รายการ กดแล้วส่งเป็นคำถาม AC2: suggestion แสดงเฉพาะที่คำตอบล่าสุดเท่านั้น | K39: 2 | L39: เสร็จแล้ว
A40: 36 | B40: FR-CHAT-014 | C40: M2 | D40: แชทถามกฎหมาย (หน้าจอและการใช้งาน) | E40: การ์ด "ขั้นตอนถัดไป" (Next-step Cards) | F40: ระบบต้องแสดงการ์ดลิงก์ไปยังคู่มือ (M5), แบบหนังสือ (M6) หรือบทความ (M3) ที่เกี่ยวข้อง จากฟิลด์ next_steps[] (type: guide, template, article) ของ event suggestions โดยอ้างอิงเฉพาะเนื้อหาที่มีอยู่ในคลัง | G40: all | H40: Must (ต้องมี) | I40: P1 | J40: AC1: Given คำตอบเรื่องบอกเลิกสัญญา Then อาจแสดงการ์ดคู่มือหรือแบบหนังสือที่เกี่ยวข้องซึ่งลิงก์ไปหน้าจริง AC2: การ์ดที่ลิงก์ไปเนื้อหาที่ไม่มีอยู่/ไม่ published ต้องไม่ถูกแสดง (ตรวจฝั่ง AI service) | K40: 2 | L40: เสร็จแล้ว
A41: 37 | B41: FR-CHAT-015 | C41: M2 | D41: แชทถามกฎหมาย (หน้าจอและการใช้งาน) | E41: Glossary Tooltip | F41: ระบบต้อง highlight ศัพท์กฎหมายในคำตอบที่มีใน kb.glossary_terms (เฉพาะครั้งแรกที่พบในแต่ละคำตอบ) และแสดงคำอธิบายสั้นเมื่อ hover/tap พร้อมลิงก์ไปหน้าอภิธานศัพท์ | G41: all | H41: Should (ควรมี) | I41: P1 | J41: AC1: Given คำตอบมีคำว่า "นิติกรรม" Then คำนั้นมีเส้นใต้ประ และ tooltip แสดงคำอธิบาย AC2: tooltip เข้าถึงได้ด้วยคีย์บอร์ด (focusable, aria-describedby) AC3: highlight ทำหลัง stream จบ (ไม่ทำระหว่าง stream) | K41: 3 | L41: กำลังทำ | O41: ไฮไลต์ศัพท์ทำระหว่างที่คำตอบกำลังไหลอยู่ ยังไม่รอจนสตรีมจบ
...

Sheet ข้อกำหนดคุณภาพ (NFR)
A1: ข้อกำหนดคุณภาพที่ MVP ต้องผ่าน
A2: 73 ข้อ · ใช้กับทุกฟีเจอร์ · ที่มา docs/02-srs.md §5 ฉบับ 1.8 (1 ต.ค. 2569)
A4: ลำดับ | B4: รหัส | C4: หมวด | D4: ข้อกำหนด | E4: เป้าหมาย | F4: วิธีวัด | G4: สถานะ/ผลตรวจล่าสุด (ตาม SRS)
A5: 1 | B5: NFR-PERF-001 | C5: Performance | D5: TTFT ของแชท (ส่ง → chunk แรก) | E5: p50 ≤ 1.5s, p95 ≤ 3s (ไม่รวมคิวเมื่อเกิน capacity) | F5: APM + ตัวชี้วัดของ AI service | G5: ผลตรวจ 30 ก.ย. 2569: ~21 VUs p95 144 ms; 200 streams พร้อมกัน p95 3.48 s (เกิน 3 s เล็กน้อย) (spec §7.13 E)
A6: 2 | B6: NFR-PERF-002 | C6: Performance | D6: Page load (LCP) หน้า content บน 4G จำลอง | E6: ≤ 2.5s p75 | F6: Lighthouse CI / RUM
A7: 3 | B7: NFR-PERF-003 | C7: Performance | D7: Search latency (search) | E7: ≤ 800ms p95 | F7: APM | G7: ผลตรวจ 30 ก.ย. 2569: ค้นหา p95 149 ms (~21 VUs), 695 ms (58 VUs) — ผ่าน
A8: 4 | B8: NFR-PERF-004 | C8: Performance | D8: JSON API ทั่วไป | E8: ≤ 300ms p95 | F8: APM | G8: ผลตรวจ 30 ก.ย. 2569: API ทั่วไป p95 88 ms (~21 VUs) ผ่าน; 406 ms ที่ 58 VUs พร้อมกันบนเครื่องทดสอบที่ใช้ร่วม (ไม่ผ่าน) — ต้องรันหลาย instance/แยกเครื่อง และวัดซ้ำบนเครื่อง production
A9: 5 | B9: NFR-PERF-005 | C9: Performance | D9: Concurrent chat streams | E9: 200 streams พร้อมกัน | F9: load test (k6) | G9: ผลตรวจ 30 ก.ย. 2569: 200 streams พร้อมกันสำเร็จ 1,939/1,939 ไม่มีข้อผิดพลาด ; TTFT เกินเป้าเล็กน้อย
A10: 6 | B10: NFR-PERF-006 | C10: Performance | D10: เวลาจบคำตอบ (complete) | E10: p95 ≤ 30s | F10: APM | G10: ผลตรวจ 30 ก.ย. 2569: แชทจบ p95 5.8 s (~21 VUs), 21.4 s (200 streams) — ผ่านเกณฑ์ 30 s
A11: 7 | B11: NFR-PERF-007 | C11: Performance | D11: JS/CSS ขนาด (gzip) ที่โหลดครั้งแรก | E11: ≤ 250KB (ไม่รวม lazy-load) | F11: CI budget
A12: 8 | B12: NFR-PERF-008 | C12: Performance | D12: Reindex หลัง publish | E12: ≤ 10 นาที | F12: job metrics
A13: 9 | B13: NFR-PERF-009 | C13: Performance | D13: หน้า login/register/legal เรนเดอร์ฝั่ง server มี <title>/meta description ต่อหน้า, มี sitemap.xml + robots.txt; หน้าแชท/หลังบ้าน/แชร์ตั้ง noindex (หน้าคลังความรู้อยู่หลัง login จึงไม่ถูกจัดทำดัชนี) | E13: <title> ครบทุกหน้า, หน้าที่ต้อง noindex ไม่ปรากฏใน sitemap | F13: ตรวจใน web/tests/screens.mjs
A14: 10 | B14: NFR-REL-001 | C14: Reliability & Availability | D14: Availability ของบริการเว็บ (ไม่รวม maintenance ที่แจ้งล่วงหน้า) | E14: 99.5% ต่อเดือน
A15: 11 | B15: NFR-REL-002 | C15: Reliability & Availability | D15: Backup DB | E15: full รายวัน + WAL archiving; RPO ≤ 24 ชม. | G15: ผลตรวจ 30 ก.ย. 2569: บางส่วน: backup รายวันเข้ารหัสด้วย scripts/backup.sh (RPO = ช่วงห่างของ backup); ยังไม่มี WAL archiving และยังไม่ได้ติดตั้ง timer (ต้อง sudo)
A16: 12 | B16: NFR-REL-003 | C16: Reliability & Availability | D16: Restore | E16: RTO ≤ 4 ชม.; ทดสอบ restore ทุกไตรมาส | G16: ผลตรวจ 30 ก.ย. 2569: บางส่วน: scripts/restore-test.sh กู้ลงฐานข้อมูลชั่วคราวและตรวจได้ใน ~10 วินาที (ข้อมูลทดสอบเล็ก); ยังไม่ได้ซ้อมกู้บนเครื่องอื่นและยังไม่ได้วัด RTO จริง
A17: 13 | B17: NFR-REL-004 | C17: Reliability & Availability | D17: Graceful degradation | E17: เมื่อ AI service ไม่พร้อม: หน้าอ่านเนื้อหา (คลังความรู้/ตัวบท/คู่มือ) ยังใช้ได้, แชทแสดงข้อความ unavailable
A18: 14 | B18: NFR-REL-005 | C18: Reliability & Availability | D18: Job retry | E18: job ล้มเหลว retry แบบ exponential backoff สูงสุด 5 ครั้ง แล้วเข้า dead-letter + แจ้ง admin
A19: 15 | B19: NFR-SEC-001 | C19: Security | D19: OWASP ASVS 4.0 Level 2 สำหรับ web tier; ผ่าน pentest ก่อนเปิด P1 | G19: ผลตรวจ 30 ก.ย. 2569: บางส่วน: ตรวจภายใน (audit dependency, gitleaks, ZAP baseline, e2e สิทธิ์) — ยังไม่มี pentest โดยบุคคลที่สาม ซึ่งเกณฑ์กำหนดก่อนเปิด P1
A20: 16 | B20: NFR-SEC-002 | C20: Security | D20: รหัสผ่านเก็บด้วย scrypt (ค่าเริ่มต้นของ Better Auth) ไม่เก็บรหัสผ่านเป็นข้อความธรรมดา
A21: 17 | B21: NFR-SEC-003 | C21: Security | D21: Session cookie lc.session_token (Better Auth, cookie prefix lc, DB session ใน Postgres) HttpOnly; Secure; SameSite=Lax, ออก session ใหม่เมื่อ login/เปลี่ยนสิทธิ์; CSRF: ตรวจ Origin + token X-CSRF-Token
A22: 18 | B22: NFR-SEC-004 | C22: Security | D22: Security headers: CSP (ไม่อนุญาต inline script ยกเว้น nonce/hash ที่กำหนด), HSTS, X-Content-Type-Options, X-Frame-Options SAMEORIGIN, Referrer-Policy, Permissions-Policy, COOP — อย่างน้อยเทียบเท่า AI-EDW
A23: 19 | B23: NFR-SEC-005 | C23: Security | D23: SQL: prepared statements เท่านั้น; ไม่มี dynamic SQL จาก input
A24: 20 | B24: NFR-SEC-006 | C24: Security | D24: บัญชี editor/reviewer/admin ต้องเปิด TOTP 2FA
A25: 21 | B25: NFR-SEC-007 | C25: Security | D25: Rate limit: login 10/นาที/IP, API 120/นาที/ผู้ใช้, stream 3 พร้อมกัน/ผู้ใช้, share password 5 ครั้ง/15 นาที | G25: ผลตรวจ 30 ก.ย. 2569: ทำแล้ว: API 120/นาที/ผู้ใช้ (Redis), stream 3 พร้อมกัน, sign-in 10/นาที/IP, ล็อกรหัสผ่านลิงก์แชร์ต่อลิงก์ + เพิ่ม 20/นาที/IP; เพิ่มแชท 12/นาที (guest 6), อัปโหลด 6/นาที
A26: 22 | B26: NFR-SEC-008 | C26: Security | D26: Secrets ใน env/secret store เท่านั้น (ไม่มีใน git — ตรวจด้วย gitleaks); คีย์ของ API ภายนอก (ฐานความรู้ของบริษัท) อยู่เฉพาะ AI service
A27: 23 | B27: NFR-SEC-009 | C27: Security | D27: Dependency scanning (pnpm audit, pip-audit) และ container scanning ใน CI; ไม่มีช่องโหว่ระดับ High/Critical ที่ยังไม่แก้ก่อน release | G27: ผลตรวจ 30 ก.ย. 2569: บางส่วน: pnpm audit (1 moderate ใน dev tooling), pip-audit (0), gitleaks (0) ผ่าน scripts/security-scan.sh; ยังไม่มี CI/container scanning
A28: 24 | B28: NFR-SEC-011 | C28: Security | D28: ไฟล์อัปโหลด: ตรวจ MIME จริง (magic bytes), จำกัดขนาด, สแกนไวรัส, เก็บนอก web root, เสิร์ฟผ่าน signed URL
A29: 25 | B29: NFR-SEC-012 | C29: Security | D29: Tenant isolation: ทุกตารางที่เป็นขององค์กรมี org_id; ทุก query ผ่าน data-access layer ที่บังคับเงื่อนไข org_id + membership; ชุดทดสอบ cross-tenant อัตโนมัติผ่าน 100% ทุก PR; pentest ครอบคลุม IDOR ข้ามองค์กร
A30: 26 | B30: NFR-PRIV-001 | C30: Privacy (PDPA) | D30: มีประกาศความเป็นส่วนตัว (privacy notice) ภาษาไทย/อังกฤษ ระบุวัตถุประสงค์, ฐานทางกฎหมาย, ระยะเวลาเก็บ, ผู้รับข้อมูล (รวม API ฐานความรู้ของบริษัทเมื่อเปิดใช้), สิทธิเจ้าของข้อมูล, ช่องทางติดต่อ DPO
A31: 27 | B31: NFR-PRIV-002 | C31: Privacy (PDPA) | D31: Consent แยกวัตถุประสงค์และถอนได้ (FR-AUTH-009/010); บันทึกหลักฐาน consent
A32: 28 | B32: NFR-PRIV-003 | C32: Privacy (PDPA) | D32: ข้อมูลที่อาจเป็นข้อมูลอ่อนไหวที่ระบบเก็บ (ไฟล์สัญญาและข้อความที่สกัด — NFR-PRIV-009) เข้ารหัส (AES-256-GCM, envelope encryption, key แยกจาก DB)
A33: 29 | B33: NFR-PRIV-004 | C33: Privacy (PDPA) | D33: PII masking ก่อนค้นหา บันทึก และส่งไป API ภายนอก (FR-AI-012); ไม่ส่ง user id/อีเมลไปยัง API ภายนอก
A34: 30 | B34: NFR-PRIV-005 | C34: Privacy (PDPA) | D34: Data minimization: application log ไม่มีข้อความแชทดิบ/เนื้อหาคดี; analytics ใช้ข้อมูลแบบรวมหรือ pseudonymized
A35: 31 | B35: NFR-PRIV-006 | C35: Privacy (PDPA) | D35: สิทธิเจ้าของข้อมูล: เข้าถึง/ขอสำเนา (FR-AUTH-017), ลบ (FR-AUTH-018), แก้ไข (โปรไฟล์), คัดค้าน/ถอน consent — ดำเนินการภายใน 30 วัน
A36: 32 | B36: NFR-PRIV-007 | C36: Privacy (PDPA) | D36: Retention ตาม §6.2 และ job ลบอัตโนมัติที่ตรวจสอบได้ (log จำนวนที่ลบ)
A37: 33 | B37: NFR-PRIV-008 | C37: Privacy (PDPA) | D37: มี data breach runbook: แจ้ง สคส. ภายใน 72 ชม. ตามหลักเกณฑ์ PDPA (ดู 03-technical-spec.md §7)
A38: 34 | B38: NFR-PRIV-009 | C38: Privacy (PDPA) | D38: ข้อมูลสัญญาขององค์กร: ไฟล์และข้อความที่สกัดเข้ารหัส (AES-256-GCM) แยก key ต่อองค์กรได้; เก็บตาม retention ขององค์กร (BR-024); ไม่ใช้นอกวัตถุประสงค์ของบริการ (FR-CR-010); มี DPA (องค์กร = ผู้ควบคุมข้อมูล, ผู้ให้บริการ = ผู้ประมวลผล) ก่อนเริ่มใช้งาน
A39: 35 | B39: NFR-A11Y-001 | C39: Accessibility | D39: สอดคล้อง WCAG 2.2 ระดับ AA ทุกหน้าผู้ใช้ปลายทาง
A40: 36 | B40: NFR-A11Y-002 | C40: Accessibility | D40: Contrast ข้อความปกติ ≥ 4.5:1, ข้อความใหญ่/ไอคอน ≥ 3:1 ทั้ง light และ dark | G40: ผลตรวจ 30 ก.ย. 2569: axe ไม่พบ contrast ผิดใน 124 ชุด (light/dark, ไทย/อังกฤษ, desktop/375px) หลังแก้ token
A41: 37 | B41: NFR-A11Y-003 | C41: Accessibility | D41: ใช้งานด้วยคีย์บอร์ดได้ครบ, focus ring ชัดเจน, focus trap ใน modal/drawer, Esc ปิด
...

Sheet กฎธุรกิจ (BR)
A1: กฎธุรกิจ
A2: 23 ข้อ · ที่มา docs/02-srs.md §7 ฉบับ 1.8 (1 ต.ค. 2569)
A4: ลำดับ | B4: รหัส | C4: กฎ
A5: 1 | B5: BR-001 | C5: Quota ข้อความแชทต่อวัน (ตั้งด้วย env GUEST_DAILY_MESSAGES / MEMBER_DAILY_MESSAGES; staff คงที่ 300; นับใน app.usage_counters): guest 10, member 100, editor/reviewer/admin 300; รีเซ็ต 00:00 Asia/Bangkok; regenerate นับ 1; ข้อความที่ล้มเหลวจากฝั่งระบบไม่นับ
A6: 2 | B6: BR-002 | C6: ความยาวข้อความผู้ใช้สูงสุด 4,000 อักษร
A7: 3 | B7: BR-003 | C7: แชทของ guest ถูกลบถาวรเมื่อไม่มีการใช้งาน 24 ชม.
A8: 4 | B8: BR-004 | C8: ลิงก์แชร์: หมดอายุค่าเริ่มต้น 30 วัน, สูงสุด 365 วัน; รหัสผ่านไม่บังคับ (ถ้าตั้ง ≥ 6 อักษร); ผู้ใช้ 1 คนมีลิงก์ active ได้ ≤ 50
A9: 5 | B9: BR-005 | C9: Disclaimer: (ก) footer ทุกหน้า (ข) ท้ายทุกคำตอบเชิงกฎหมาย (ค) ทุกเอกสารที่สร้าง — ข้อความมาตรฐานมาจาก i18n และแก้ได้เฉพาะ admin + reviewer
A10: 6 | B10: BR-006 | C10: Safety escalation categories (ตาม 03-technical-spec.md §0.2): domestic_violence (รวมความรุนแรงทางเพศ), child_abuse (รวมการค้ามนุษย์ที่เกี่ยวกับเด็ก), self_harm, threat_violence (ถูกขู่/อันตรายต่อชีวิต รวมการค้ามนุษย์), arrest_detention, scam_in_progress (กำลังถูกหลอกโอนเงิน), deadline_imminent (เรื่องที่มีกำหนดเวลาใกล้ถึง เช่น วันนัดศาล หมายเรียก อายุความ) — ระดับ urgent หรือ caution; จัดระดับด้วยชุดคำสำคัญ และหมายเลขติดต่อต้องมาจากข้อมูลที่ตรวจยืนยันแล้วเท่านั้น (ปัจจุบันยังไม่มี)
A11: 7 | B11: BR-007 | C11: Content lifecycle: draft → in_review → published → archived; การตีกลับ = review action requested_changes → กลับเป็น draft แล้วส่ง in_review ใหม่ได้ (วนได้หลายรอบ); ผู้อนุมัติ ≠ ผู้ส่งเข้าตรวจล่าสุด; published แก้ตรงไม่ได้ (สร้าง draft เวอร์ชันใหม่)
A12: 8 | B12: BR-008 | C12: รอบทบทวน (review_due_at): เนื้อหา (บทความ/คู่มือ/แบบหนังสือ) ที่อ้างมาตราซึ่งถูกแก้ไขต้องถูกตั้ง review_due_at ทันทีเมื่อตัวบทฉบับใหม่ได้รับอนุมัติ (FR-ADM-009)
A13: 9 | B13: BR-009 | C13: การเลือกเวอร์ชันตัวบท: ใช้เวอร์ชันที่ effective_from ≤ วันที่อ้างอิง (as_of, ค่าเริ่มต้น = วันนี้) < effective_to; ห้ามลบเวอร์ชันเก่า ให้ปิดวันแทน
A14: 10 | B14: BR-010 | C14: Citation อ้างได้เฉพาะ: มาตราในตัวบทที่มีในคลัง และบทความ/คู่มือ/คำศัพท์ในคลัง (published; ฉบับร่างเฉพาะระบบทดสอบและติดป้ายฉบับร่าง)
A15: 11 | B15: BR-012 | C15: ลบบัญชี: pending_deletion 30 วัน (login เพื่อยกเลิกได้) → ลบถาวร; audit log เก็บแบบ pseudonymized จนครบ 1 ปี
A16: 12 | B16: BR-013 | C16: ชื่อแชท: ตั้งอัตโนมัติ 1 ครั้งหลังคำตอบแรก, ≤ 60 อักษร, ไม่มี PII; ถ้าผู้ใช้เปลี่ยนชื่อเอง ตั้ง app.chats.title_source = 'user' และระบบจะไม่เขียนทับ
... A27: 23 | B27: BR-027 | C27: ข้อความในระบบห้ามอ้างว่าเนื้อหา/ผลตรวจผ่านการตรวจหรือรับรองโดยบุคคลหรือหน่วยงานใด เว้นแต่มีบันทึกการ approve จริงใน kb.content_reviews

Sheet หลังเฟส MVP
A1: ฟีเจอร์ที่ไม่อยู่ใน MVP (เฟส 2–3)
A2: 50 ฟีเจอร์ · ไว้ดูขอบเขต ยังไม่ต้องทำในรอบนี้ · ไม่อยู่ใน docs/02-srs.md ฉบับ 1.8 (ฟีเจอร์ที่เคยอยู่ใน MVP แล้วถูกตัดออกย้ายมาไว้ที่นี่ เฟส P2)
A4: ลำดับ | B4: รหัส | C4: โมดูล | D4: ชื่อโมดูล | E4: ฟีเจอร์ | F4: รายละเอียด | G4: ความสำคัญ | H4: เฟส
A5: 1 | B5: FR-AUTH-020 | C5: M1 | D5: บัญชีผู้ใช้และการเข้าถึง | E5: เข้าสู่ระบบด้วย Google / LINE | F5: ระบบควรรองรับ OAuth 2.0 / OpenID Connect กับ Google และ LINE Login; ผูกกับบัญชีอีเมลเดิมได้หลังยืนยัน | G5: Should (ควรมี) | H5: P2
A6: 2 | B6: FR-CHAT-024 | C6: M2 | D6: แชทถามกฎหมาย (หน้าจอและการใช้งาน) | E6: ลากจัดลำดับ/ย้ายเข้าโฟลเดอร์ | F6: ระบบต้องให้ลากแชทเพื่อจัดลำดับหรือวางลงโฟลเดอร์ (desktop) และมีเมนู "ย้ายไปโฟลเดอร์…" สำหรับมือถือ/คีย์บอร์ด | G6: Could (อาจมี) | H6: P2
A7: 3 | B7: FR-CHAT-033 | C7: M2 | D7: แชทถามกฎหมาย (หน้าจอและการใช้งาน) | E7: แนบไฟล์ในแชท | F7: ระบบควรให้แนบรูป (jpg/png/webp) หรือ PDF ในแชทผ่านปุ่มแนบหรือ drag & drop เพื่อให้ระบบอ่านเอกสาร (เช่น สัญญา, หมายศาล, ใบสั่ง) ประกอบการค้นข้อมูลที่เกี่ยวข้อง โดยต้องมี consent ข้อมูลอ่อนไหวและแสดงคำเตือนข้อมูลส่วนบุคคลก่อนส่ง (การอัปโหลดสัญญาขององค์กรมีแล้วใน M12) | G7: Should (ควรมี) | H7: P2
A8: 4 | B8: FR-CHAT-035 | C8: M2 | D8: แชทถามกฎหมาย (หน้าจอและการใช้งาน) | E8: อ่านออกเสียงคำตอบ | F8: ระบบอาจมีปุ่มอ่านออกเสียงคำตอบด้วย Web Speech API (ภาษาไทย) โดยข้าม citation markers | G8: Could (อาจมี) | H8: P2
A9: 5 | B9: FR-KB-004 | C9: M3 | D9: คลังความรู้ | E9: สลับระดับเนื้อหา | F9: เมื่อบทความมีหลายระดับของหัวข้อเดียวกัน (group เดียวกัน) ระบบควรมีตัวสลับ "อ่านแบบง่าย / แบบปฏิบัติ / แบบเชิงลึก" | G9: Should (ควรมี) | H9: P2
A10: 6 | B10: FR-KB-007 | C10: M3 | D10: คลังความรู้ | E10: ประวัติเวอร์ชันและดู ณ วันที่ | F10: ระบบต้องแสดงประวัติการแก้ไขของแต่ละมาตรา (เวอร์ชัน, effective_from/to, กฎหมายที่แก้ไข) และให้ดูตัวบท "ณ วันที่" ที่เลือก พร้อม diff ระหว่างเวอร์ชัน | G10: Should (ควรมี) | H10: P2
A11: 7 | B11: FR-KB-012 | C11: M3 | D11: คลังความรู้ | E11: ฎีกาน่ารู้ | F11: ระบบต้องแสดงคำพิพากษาศาลฎีกาที่คัดเลือก: เลขที่คำพิพากษา/ปี, ประเด็น, ข้อเท็จจริงโดยย่อ, คำวินิจฉัย, หลักที่ได้, มาตราที่เกี่ยวข้อง, ลิงก์ต้นฉบับ; ค้นด้วยเลขฎีกาได้ (เช่น "ฎีกา 1234/2560") | G11: Should (ควรมี) | H11: P2
A12: 8 | B12: FR-KB-013 | C12: M3 | D12: คลังความรู้ | E12: FAQ | F12: ระบบต้องมี FAQ ต่อหมวดแบบ accordion (คำถาม-คำตอบสั้นพร้อม citation) และใช้เป็นการ์ดตัวอย่างคำถามได้ | G12: Should (ควรมี) | H12: P2
A13: 9 | B13: FR-KB-017 | C13: M3 | D13: คลังความรู้ | E13: ไฮไลต์และโน้ตส่วนตัว | F13: ระบบอาจให้ member ไฮไลต์ข้อความในบทความ/ตัวบทและเพิ่มโน้ตส่วนตัว | G13: Could (อาจมี) | H13: P2
A14: 10 | B14: FR-LRN-001 | C14: M4 | D14: เรียนจาก 0 | E14: แคตตาล็อกหลักสูตร | F14: ระบบต้องแสดง /learn: การ์ดหลักสูตร (ชื่อ, คำอธิบาย, ระดับ, จำนวนบทเรียน, เวลาเรียนรวมโดยประมาณ, ความก้าวหน้าของผู้ใช้) และส่วน "เรียนต่อจากที่ค้าง" | G14: Must (ต้องมี) | H14: P2
A15: 11 | B15: FR-LRN-002 | C15: M4 | D15: เรียนจาก 0 | E15: หน้าหลักสูตร | F15: ระบบต้องแสดงรายการบทเรียนเรียงลำดับ พร้อมสถานะ (ล็อก / พร้อมเรียน / เรียนแล้ว / ผ่าน quiz), วัตถุประสงค์การเรียนรู้ และแถบความก้าวหน้า % | G15: Must (ต้องมี) | H15: P2
A16: 12 | B16: FR-LRN-003 | C16: M4 | D16: เรียนจาก 0 | E16: หน้าบทเรียน | F16: ระบบต้องแสดงบทเรียน (markdown + รูป/infographic + citation + glossary tooltip), เวลาอ่าน, ปุ่ม "ก่อนหน้า/ถัดไป", "ทำแบบทดสอบ" และ "ถามนิติมิตรเกี่ยวกับบทนี้" | G16: Must (ต้องมี) | H16: P2
... A54: 50 | B54: FR-ADM-020 | C54: M10 | D54: ระบบหลังบ้าน | E54: Authoring หลักสูตรและ Quiz | F54: ระบบต้องให้สร้างหลักสูตร (ลำดับบทเรียน, โหมด sequential/free), บทเรียน, คำถาม quiz (ชนิด, ตัวเลือก, เฉลย, คำอธิบาย, citation, เกณฑ์ผ่าน) ผ่าน review workflow | G54: Must (ต้องมี) | H54: P2
